## 不可恢复错误与panic!

> panic中的栈展开与终止
> 
> 当panic发生时，程序会默认开始栈展开。这意味着Rust会沿着调用栈的反向顺序遍历所有调用函数，并依次清理这些函数中的数据。
>
> 通过在Cargo.toml 文件中的[profile]区域添加panic = 'abort'来将panic的默认行为从展开切换为终止

```rust
[profile.release]
panic = 'abort'
```

panic的使用
```rust
src/main.rs

fn main() {
    panic!("crash and burn");
}
```

### 使用panic! 产生的回溯信息

## 可恢复错误与Result

Result枚举定义了两个变体—Ok和Err
```rust
enum Result<T, E> {
    Ok(T),
    Err(E),
}
```
T和E是泛型参数:

T代表了Ok变体中包含的值类型，该变体中的值会在执行成功时返回；而E则代表了Err变体中包含的错误类型，该变体中的值会在执行失败时返回。

```rust
src/main.rs
use std::fs::File;

fn main() {
    // File::open会返回一个Result
    let f = File::open("hello.txt");

    // 使用match表达式来处理所有可能的Result变体
    let f = match f {
        Ok(file) => file,
        Err(error) => {
            panic!("There was a problem opening the file: {:?}", error)
        },
    };
}
```

### 匹配不同的错误
```rust
src/main.rs
use std::fs::File;
use std::io::ErrorKind;

1. 使用match
fn main() {
    let f = File::open("hello.txt");

    let f = match f {
        Ok(file) => file,
        Err(error) => match error.kind() {
            // 根据不同的错误进行不同的处理
            ErrorKind::NotFound => match File::create("hello.txt") {
                Ok(fc) => fc,
                Err(e) => panic!("Tried to create file but there was a problem: {:?}", e),
            },
            other_error => panic!("There was a problem opening the file: {:?}", other_error),
        },
    };
}
```

2. 使用if
```rust
fn main() {
    let f = File::open("hello.txt").map_err(|error| {
        if error.kind() == ErrorKind::NotFound {
            File::create("hello.txt").unwrap_or_else(|error| {
                panic!("Tried to create file but there was a problem: {:?}", error);
            })
        } else {
            panic!("There was a problem opening the file: {:?}", error);
        }
    });
}
```

### 失败时触发panic的快捷方式：unwrap和expect
当Result的返回值是Ok变体时，unwrap就会返回Ok内部的值。而当Result的返回值是Err变体时，unwrap则会替我们调用panic! 宏。

expect的方法，允许我们在unwrap的基础上指定panic! 所附带的错误提示信息。

区别在于，expect触发panic! 时会将传入的参数字符串作为错误提示信息输出，而unwrap触发的panic! 则只会携带一段简短的默认信息。

### 传播错误
传播错误：除了可以在函数中处理这个错误，还可以将这个错误返回给调用者，让他们决定应该如何做进一步处理。

```rust
use std::io;
use std::io::Read;
use std::fs::File;

fn read_username_from_file() -> Result<String, io::Error> ❶ {
 ❷ let f = File::open("hello.txt");

 ❸ let mut f = match f {
        Ok(file) => file,
        Err(e) => return Err(e),
    };

 ❹ let mut s = String::new();

 ❺ match f.read_to_string(&mut s)❻ {
        Ok(_) => Ok(s)❼,
        Err(e) => Err(e)❽,
    }
}
```
❶ 返回类型：Result<String, io::Error>，其中的泛型参数T被替换为具体的String类型，而泛型E则被替换为具体的io::Error类型

#### 传播错误的快捷方式：?运算符
```rust
src/main.rs
use std::io;
use std::io::Read;
use std::fs::File;

fn read_username_from_file() -> Result<String, io::Error> {
    let mut f = File::open("hello.txt")?;
    let mut s = String::new();
    f.read_to_string(&mut s)?;
    Ok(s)
}
```

#### ?运算符后面的链式方法调用
```rust
src/main.rs
use std::io;
use std::io::Read;
use std::fs::File;

fn read_username_from_file() -> Result<String, io::Error> {
    let mut s = String::new();

    File::open("hello.txt")?.read_to_string(&mut s)?;

    Ok(s)
}
```

#### 使用fs::read_to_string读取文件

```rust
src/main.rs
use std::io;
use std::fs;

fn read_username_from_file() -> Result<String, io::Error> {
    fs::read_to_string("hello.txt")
}
```

## panic!

### 错误处理的指导原则
* 损坏状态并不包括预期中会偶尔发生的事情。

* 随后的代码无法在出现损坏状态后继续正常运行。

* 没有合适的方法来将“处于损坏状态”这一信息编码至我们所使用的类型中。

但是，假如错误是可预期的，那么就应该返回一个Result而不是调用panic!。